Tue Nov 23 16:02:53 CET 2021 : Servidor de red Apache Derby: Se ha iniciado 10.14.2.0 - (1828579) y está listo para aceptar las conexiones en el puerto 1527
----------------------------------------------------------------
Tue Nov 23 16:03:01 CET 2021:
 Iniciando instancia a816c00e-017d-4d52-2456-ffffcf1bb56f de Derby, versión The Apache Software Foundation - Apache Derby - 10.14.2.0 - (1828579): 
en el directorio de base de datos C:\Users\root\Documents\GitHub\RepoCompartido\Proyecto05\src\controlador\empresa con el cargador de clases jdk.internal.loader.ClassLoaders$AppClassLoader@c387f44
Cargado desde file:/C:/Users/root/Desktop/DriversDB/db-derby-10.14.2.0-bin/lib/derby.jar
java.vendor=Oracle Corporation
java.runtime.version=13.0.2+8
user.dir=C:\Users\root\Desktop\DriversDB\db-derby-10.14.2.0-bin
os.name=Windows 10
os.arch=amd64
os.version=10.0
derby.system.home=C:\Users\root\Documents\GitHub\RepoCompartido\Proyecto05\src\controlador
Cargador de clases de base de datos iniciado - derby.database.classpath=''
Tue Nov 23 16:03:01 CET 2021 Thread[DRDAConnThread_2,5,main] (XID = 466), (SESSIONID = 0), (DATABASE = empresa), (DRDAID = {1}), Cleanup action starting
java.sql.SQLNonTransientConnectionException: Se ha producido un fallo de autenticación de conexión. Motivo: Autenticación no válida..
	at org.apache.derby.impl.jdbc.SQLExceptionFactory.getSQLException(Unknown Source)
	at org.apache.derby.impl.jdbc.SQLExceptionFactory.getSQLException(Unknown Source)
	at org.apache.derby.impl.jdbc.Util.generateCsSQLException(Unknown Source)
	at org.apache.derby.impl.jdbc.Util.generateCsSQLException(Unknown Source)
	at org.apache.derby.impl.jdbc.EmbedConnection.newSQLException(Unknown Source)
	at org.apache.derby.impl.jdbc.EmbedConnection.checkUserCredentials(Unknown Source)
	at org.apache.derby.impl.jdbc.EmbedConnection.<init>(Unknown Source)
	at org.apache.derby.jdbc.InternalDriver$1.run(Unknown Source)
	at org.apache.derby.jdbc.InternalDriver$1.run(Unknown Source)
	at java.base/java.security.AccessController.doPrivileged(AccessController.java:554)
	at org.apache.derby.jdbc.InternalDriver.getNewEmbedConnection(Unknown Source)
	at org.apache.derby.jdbc.InternalDriver.connect(Unknown Source)
	at org.apache.derby.jdbc.InternalDriver.connect(Unknown Source)
	at org.apache.derby.jdbc.EmbeddedDriver.connect(Unknown Source)
	at org.apache.derby.impl.drda.Database.makeConnection(Unknown Source)
	at org.apache.derby.impl.drda.DRDAConnThread.getConnFromDatabaseName(Unknown Source)
	at org.apache.derby.impl.drda.DRDAConnThread.verifyUserIdPassword(Unknown Source)
	at org.apache.derby.impl.drda.DRDAConnThread.parseSECCHK(Unknown Source)
	at org.apache.derby.impl.drda.DRDAConnThread.parseDRDAConnection(Unknown Source)
	at org.apache.derby.impl.drda.DRDAConnThread.processCommands(Unknown Source)
	at org.apache.derby.impl.drda.DRDAConnThread.run(Unknown Source)
Caused by: ERROR 08004: Se ha producido un fallo de autenticación de conexión. Motivo: Autenticación no válida..
	at org.apache.derby.iapi.error.StandardException.newException(Unknown Source)
	at org.apache.derby.impl.jdbc.SQLExceptionFactory.wrapArgsForTransportAcrossDRDA(Unknown Source)
	... 21 more
============= begin nested exception, level (1) ===========
ERROR 08004: Se ha producido un fallo de autenticación de conexión. Motivo: Autenticación no válida..
	at org.apache.derby.iapi.error.StandardException.newException(Unknown Source)
	at org.apache.derby.impl.jdbc.SQLExceptionFactory.wrapArgsForTransportAcrossDRDA(Unknown Source)
	at org.apache.derby.impl.jdbc.SQLExceptionFactory.getSQLException(Unknown Source)
	at org.apache.derby.impl.jdbc.SQLExceptionFactory.getSQLException(Unknown Source)
	at org.apache.derby.impl.jdbc.Util.generateCsSQLException(Unknown Source)
	at org.apache.derby.impl.jdbc.Util.generateCsSQLException(Unknown Source)
	at org.apache.derby.impl.jdbc.EmbedConnection.newSQLException(Unknown Source)
	at org.apache.derby.impl.jdbc.EmbedConnection.checkUserCredentials(Unknown Source)
	at org.apache.derby.impl.jdbc.EmbedConnection.<init>(Unknown Source)
	at org.apache.derby.jdbc.InternalDriver$1.run(Unknown Source)
	at org.apache.derby.jdbc.InternalDriver$1.run(Unknown Source)
	at java.base/java.security.AccessController.doPrivileged(AccessController.java:554)
	at org.apache.derby.jdbc.InternalDriver.getNewEmbedConnection(Unknown Source)
	at org.apache.derby.jdbc.InternalDriver.connect(Unknown Source)
	at org.apache.derby.jdbc.InternalDriver.connect(Unknown Source)
	at org.apache.derby.jdbc.EmbeddedDriver.connect(Unknown Source)
	at org.apache.derby.impl.drda.Database.makeConnection(Unknown Source)
	at org.apache.derby.impl.drda.DRDAConnThread.getConnFromDatabaseName(Unknown Source)
	at org.apache.derby.impl.drda.DRDAConnThread.verifyUserIdPassword(Unknown Source)
	at org.apache.derby.impl.drda.DRDAConnThread.parseSECCHK(Unknown Source)
	at org.apache.derby.impl.drda.DRDAConnThread.parseDRDAConnection(Unknown Source)
	at org.apache.derby.impl.drda.DRDAConnThread.processCommands(Unknown Source)
	at org.apache.derby.impl.drda.DRDAConnThread.run(Unknown Source)
============= end nested exception, level (1) ===========
Cleanup action completed
Tue Nov 23 16:03:01 CET 2021 Thread[DRDAConnThread_2,5,main] (DATABASE = empresa), (DRDAID = {1}), Se ha producido un fallo de autenticación de conexión. Motivo: Autenticación no válida..
